Workbook

Sheet Providers
A1: Provider | B1: Contact | C1: Phone | D1: Email | E1: Places | F1: Notes | G1: Agreement signed? | H1: Last contacted
A2: Greywater Vale Infirmary | B2: Sister Agda Frostmantle | C2: 01632 960501 | D2: placements@greywater-infirmary.example | E2: 12 | F2: 12 Nursing and Care placements per semester, no Year 1 in winter | G2: ? | H2: Aug 1052
A3: Hollowpick Community Care | B3: Brenik Ashbarrow | C3: 01632 960502 | D3: brenik@hollowpick-care.example | E3: 4 | F3: 4 places, requires an occupational health letter before start | G3: N
A4: Deepmarrow Hospice | B4: Lirien Boughchant | C4: 01632 960503 | D4: volunteers@deepmarrow-hospice.example | E4: 2 | F4: 2 places, Year 3 only, interview required | G4: see email | H4: last year
A5: Brinestep Coastal Clinic | B5: Marra Foamveil | C5: 01632 960504 | D5: m.foamveil@brinestep-clinic.example | E5: 6 | F5: 6 places, travel bursary needed, closed for storms in January and February | G5: see email
A6: Cragburrow Mine Surgery | B6: Durgan Brimspade | C6: 01632 960505 | D6: surgery@cragburrow.example | E6: 3 | F6: 3 places, shift pattern, students must have the underground safety briefing | G6: Y | H6: ring H
A7: Oakhollow Village Practice | B7: Dr Lirien Ferntext | C7: 01632 960506 | D7: practice.manager@oakhollow.example | E7: 2 | F7: 2 places per semester, Year 2 only, Tuesdays and Thursdays closed to students | G7: N | H7: ring H
A8: Stonebridge Residential Care Home | B8: Matron Gilda Crestguard | C8: 01632 960507 | D8: matron@stonebridge-care.example | E8: 5 | F8: 5 places, no more than 2 students on any shift, uniform must be plain navy | G8: Y | H8: Sep 1052
A9: Ashvale Community Nursing Team | B9: Vaela Kindlebloom | C9: 01632 960508 | D9: v.kindlebloom@ashvale-nursing.example | E9: 4 | F9: 4 places, students must have a bicycle or transport, home visits in pairs | G9: Y | H9: Jul 1052
A10: Greywater Vale Infirmary, Children's Ward | B10: Sister Hilda Cliffmarch | C10: 01632 960509 | D10: childrens.ward@greywater-infirmary.example | E10: 3 | F10: 3 places, enhanced clearance required, Year 2 semester 2 only | G10: see email | H10: Aug 1052
A11: Millbrook Community Mental Health Team | B11: Caedros Pyrelatch | C11: 01632 960510 | D11: placements@millbrook-cmht.example | E11: 3 | F11: 3 places, interview required, students attend a half-day induction the week before | G11: Y | H11: ring H
A12: Riverside Rehabilitation Unit | B12: Elka Dustmantle | C12: 01632 960511 | D12: e.dustmantle@riverside-rehab.example | E12: 4 | F12: 4 places, shared with Physiotherapy and OT, students rota across disciplines | G12: Y | H12: Aug 1052
A13: Deepmarrow Hospice Day Service | B13: Meluin Glossfeather | C13: 01632 960512 | D13: dayservice@deepmarrow-hospice.example | E13: 2 | F13: 2 places, Year 2 only, Wednesdays only, reflective debrief compulsory | G13: Y | H13: Jul 1052
A14: Cragburrow Mine Occupational Health Service | B14: Hask Deepgrit | C14: 01632 960513 | D14: och@cragburrow.example | E14: 2 | F14: 2 places, underground safety briefing and steel-capped boots required | G14: Y | H14: last year
A15: Bismuth Quarter Surgery | B15: Dr Thessa Gemlace | C15: 01632 960514 | D15: hello@bismuthquarter-surgery.example | E15: 1 | F15: 1 place, flexible hours, students help with the art therapy group on Fridays | G15: Y | H15: Aug 1052
A16: Palmstrand Maternity Unit | B16: Mirani Horizonchant | C16: 01632 960515 | D16: maternity.education@palmstrand.example | E16: 3 | F16: 3 places, Midwifery priority, Nursing and Care places only if unfilled by week 3 | G16: Y | H16: Aug 1052
A17: Hollowpick Domiciliary Care | B17: Calla Claymantle | C17: 01632 960516 | D17: office@hollowpick-domcare.example | E17: 6 | F17: 6 places, early starts (06:30), travel between clients on foot | G17: Y
A18: Sandstone Ferry Walk-in Clinic | B18: Garril Bargestone | C18: 01632 960517 | D18: g.bargestone@ferryclinic.example | E18: 3 | F18: 3 places, weekend shifts expected, busy market days | G18: see email | H18: Jul 1052
A19: Yewgrove Elder Care Centre | B19: Nethira Duskthorn | C19: 01632 960518 | D19: n.duskthorn@yewgrove-elders.example | E19: 4 | F19: 4 places, students must attend the memory care training day first | G19: ? | H19: ring H
A20: Obsidian Vault Infirmary | B20: Dr Morthen Glassenclave | C20: 01632 960519 | D20: education@obsidianvault-infirmary.example | E20: 8 | F20: 8 places, large teaching site, formal application form per student | G20: N | H20: Sep 1052
A21: Malachite Forge First Aid Post | B21: Brimma Bellowsmoke | C21: 01632 960520 | D21: firstaid@malachiteforge.example | E21: 2 | F21: 2 places, heat and noise, hearing protection issued, Year 2 only | G21: Y | H21: Jul 1052
A22: Slate District Nursing Service | B22: Delra Linevault | C22: 01632 960521 | D22: rota@slate-districtnursing.example | E22: 3 | F22: 3 places, rota published 6 weeks ahead and not changed, punctuality expected | G22: Y | H22: Sep 1052
A23: Rowanmere Hospice at Home | B23: Feyra Blossomvow | C23: 01632 960522 | D23: f.blossomvow@rowanmere.example | E23: 2 | F23: 2 places, students must have completed a bereavement awareness session | G23: see email
A24: Flintrock Urgent Care Centre | B24: Dorrik Firechisel | C24: 01632 960523 | D24: ucc.education@flintrock.example | E24: 4 | F24: 4 places, 12-hour shifts, no first-semester Year 2 students | G24: N | H24: last year
A25: Baobab Heights Private Clinic | B25: Serenya Ivoryscroll | C25: 01632 960524 | D25: s.ivoryscroll@baobabheights.example | E25: 2 | F25: 2 places, confidentiality agreement signed on arrival, smart dress | G25: N | H25: Aug 1052
A26: Greywater Vale Infirmary, Outpatients | B26: Agda Frostmantle | C26: 01632 960501 | D26: placements@greywater-infirmary.example | E26: 6 | F26: 6 places, counted within the Infirmary total of 12, Year 1 welcome | G26: see email | H26: Aug 1052
A27: Ashen Reach School Nursing Service | B27: Noriel Coalwhisper | C27: 01632 960525 | D27: schoolnursing@ashenreach.example | E27: 2 | F27: 2 places, enhanced clearance, term time only | G27: Y | H27: last year
A28: Hearthbind Hostel Health Outreach | B28: Merra Hearthbind | C28: 01632 960526 | D28: outreach@hearthbind-hostel.example | E28: 2 | F28: 2 places, students in pairs, evening clinics Tuesday and Thursday | G28: see email | H28: last year
A29: Palm Coast Ambulance Station | B29: Tivan Breakwave | C29: 01632 960527 | D29: station.officer@palmcoast-ambulance.example | E29: 1 | F29: 1 observer place per semester, Year 2 only, no clinical tasks | G29: Y | H29: Jul 1052
A30: Granite Ridge Prison Healthcare | B30: Astri Garrisonveil | C30: 01632 960528 | D30: healthcare.education@graniteridge.example | E30: 2 | F30: 2 places, enhanced vetting takes 8 weeks, no phones on site | G30: ? | H30: Aug 1052
A31: Vale Community Pharmacy Network | B31: Jostin Clayreach | C31: 01632 960529 | D31: training@valepharmacy.example | E31: 3 | F31: 3 places across 3 branches, Pharmacy priority, Nursing and Care observers only | G31: Y | H31: Sep 1052

Sheet Y2 S1 alloc
A1: Student ID | B1: Surname | C1: Forename | D1: Pathway | E1: Provider | F1: Mentor | G1: Start | H1: End | I1: OH cleared | J1: Mandatory training | K1: Adjustments? | L1: Notes
A2: 1052-NC-0365 | B2: Ashbarrow | C2: Braniel | D2: Adult | E2: Hollowpick Community Care | F2: Ashbarrow | G2: 1052-10-06 | I2: Y | K2: yes - no nights wk 1-2 | L2: repeat placement
A3: 1052-NC-7744 | B3: Bannerstone | C3: Astri | D3: Adult | E3: Greywater Vale Infirmary, Children's Ward | F3: Cliffmarch | G3: 1052-10-06 | I3: Y
A4: 1052-NC-7755 | B4: Blazewind | C4: Alira | D4: Community | E4: Stonebridge Residential Care Home | G4: 1052-10-06 | I4: N | L4: ring provider re start date
A5: 1052-NC-8383 | B5: Bloomjoint | C5: Jonel | D5: Adult | E5: Vale Community Pharmacy Network | F5: Clayreach | G5: 1052-10-06 | I5: N | J5: complete | K5: yes - no nights wk 1-2 | L5: lives near Palm Coast
A6: 1052-NC-9781 | B6: Brambletale | C6: Neren | D6: Adult | E6: Brinestep Coastal Clinic | F6: Foamveil | G6: 1052-10-06 | I6: Y (letter) | L6: lives near Palm Coast
A7: 1052-NC-7854 | B7: Bridgeglen | C7: Halden | D7: Adult | E7: Cragburrow Mine Surgery | F7: Brimspade | G7: 1052-10-06 | I7: Y (letter) | J7: done | L7: lives near Palm Coast
A8: 1052-NC-8434 | B8: Brighthaft | C8: Rokka | D8: Mental health | E8: Ashvale Community Nursing Team | F8: Kindlebloom | G8: 1052-10-06 | I8: Y
A9: 1052-NC-8880 | B9: Burnthread | C9: Fenrik | D9: Community | E9: Hearthbind Hostel Health Outreach | G9: 1052-10-06 | I9: Y | J9: complete | L9: ring provider re start date
A10: 1052-NC-6333 | B10: Ceremleaf | C10: Qiraen | D10: Adult | E10: Riverside Rehabilitation Unit | F10: Elka Dustmantle | G10: 1052-10-06 | I10: Y (letter) | J10: complete | K10: yes - no nights wk 1-2
A11: 1052-NC-5422 | B11: Cragshield | C11: Agda | D11: Community | E11: Baobab Heights Private Clinic | F11: tbc | G11: 1052-10-06 | I11: Y (letter) | J11: complete | K11: Y | L11: lives near Palm Coast
A12: 1052-NC-7540 | B12: Cragshield | C12: Krorik | D12: Community | E12: Obsidian Vault Infirmary | G12: 1052-10-06 | I12: y | J12: complete | K12: yes - no nights wk 1-2 | L12: repeat placement
A13: 1052-NC-7607 | B13: Dealroot | C13: Ilyra | D13: Mental health | E13: Deepmarrow Hospice | F13: Boughchant | G13: 1052-10-06 | I13: Y | J13: complete | K13: Y | L13: travel bursary
A14: 1052-NC-5772 | B14: Deepforge | C14: Ulgar | D14: Mental health | E14: Yewgrove Elder Care Centre | G14: 1052-10-06 | I14: y | K14: Y | L14: swap requested (no)
A15: 1052-NC-5328 | B15: Deepgrit | C15: Bolrik | D15: Adult | E15: Malachite Forge First Aid Post | G15: 1052-10-06 | I15: N | J15: 2 outstanding | K15: Y see Wellbeing
A16: 1052-NC-6639 | B16: Deepgrit | C16: Marnie | D16: Adult | E16: Sandstone Ferry Walk-in Clinic | F16: tbc | G16: 1052-10-06 | I16: N | J16: 2 outstanding | L16: travel bursary
A17: 1052-NC-8484 | B17: Deepgrit | C17: Storn | D17: Adult | E17: Flintrock Urgent Care Centre | F17: Dorrik Firechisel | G17: 1052-10-06 | I17: Y | J17: done | K17: Y see Wellbeing
A18: 1052-NC-6564 | B18: Dewscroll | C18: Meluin | D18: Adult | E18: Rowanmere Hospice at Home | F18: tbc | G18: 1052-10-06 | I18: y | J18: done | L18: travel bursary
A19: 1052-NC-7867 | B19: Draftbit | C19: Morten | D19: Adult | E19: Greywater Vale Infirmary, Outpatients | F19: Agda Frostmantle | G19: 1052-10-06 | I19: Y (letter) | K19: yes - no nights wk 1-2 | L19: travel bursary
A20: 1052-NC-8519 | B20: Duskthorn | C20: Saenil | D20: Mental health | E20: Stonebridge Residential Care Home | F20: tbc | G20: 1052-10-06 | I20: Y | J20: 2 outstanding
A21: 1052-NC-9978 | B21: Edgefitter | C21: Nerra | D21: Community | E21: Greywater Vale Infirmary, Outpatients | G21: 1052-10-06 | I21: Y (letter) | L21: ring provider re start date
A22: 1052-NC-8049 | B22: Edgefitter | C22: Sela | D22: Adult | E22: Ashvale Community Nursing Team | F22: Kindlebloom | G22: 1052-10-06 | I22: Y (letter) | J22: 2 outstanding | L22: swap requested (no)
A23: 1052-NC-5442 | B23: Emberlin | C23: Merra | D23: Mental health | E23: Cragburrow Mine Occupational Health Service | F23: tbc | G23: 1052-10-06 | I23: pending | J23: complete | K23: Y see Wellbeing | L23: travel bursary
A24: 1052-NC-7788 | B24: Emberthorn | C24: Orren | D24: Mental health | E24: Cragburrow Mine Surgery | G24: 1052-10-06 | I24: Y | J24: done | L24: repeat placement
A25: 1052-NC-5887 | B25: Flintroot | C25: Durgan | D25: Adult | E25: Sandstone Ferry Walk-in Clinic | G25: 1052-10-06 | I25: y | J25: complete | K25: Y | L25: lives near Palm Coast
A26: 1052-NC-7336 | B26: Flintroot | C26: Rilka | D26: Community | E26: Riverside Rehabilitation Unit | G26: 1052-10-06 | I26: Y | J26: done | L26: lives near Palm Coast
A27: 1052-NC-7514 | B27: Gearmantle | C27: Ralik | D27: Adult | E27: Cragburrow Mine Occupational Health Service | F27: Hask Deepgrit | G27: 1052-10-06 | I27: Y (letter) | J27: complete | L27: repeat placement
A28: 1052-NC-7941 | B28: Gemlace | C28: Dremel | D28: Mental health | E28: Greywater Vale Infirmary | F28: tbc | G28: 1052-10-06 | I28: N | K28: yes - no nights wk 1-2
A29: 1052-NC-9300 | B29: Glimmerlock | C29: Wenni | D29: Adult | E29: Greywater Vale Infirmary, Outpatients | F29: Agda Frostmantle | G29: 1052-10-06 | I29: Y | K29: Y see Wellbeing | L29: lives near Palm Coast
A30: 1052-NC-6789 | B30: Goldmantle | C30: Caerion | D30: Community | E30: Oakhollow Village Practice | G30: 1052-10-06 | I30: N | J30: complete
A31: 1052-NC-7218 | B31: Goldmantle | C31: Vaeren | D31: Community | E31: Deepmarrow Hospice | F31: tbc | G31: 1052-10-06 | I31: N | J31: done | K31: Y
A32: 1052-NC-5977 | B32: Gravelhack | C32: Enna | D32: Community | E32: Greywater Vale Infirmary | F32: tbc | G32: 1052-10-06 | I32: Y | J32: done | L32: travel bursary
A33: 1052-NC-8348 | B33: Gravelhack | C33: Fennik | D33: Mental health | E33: Hollowpick Domiciliary Care | F33: Claymantle | G33: 1052-10-06 | I33: y | K33: Y
A34: 1052-NC-7874 | B34: Gravethorn | C34: Aerthorn | D34: Adult | E34: Deepmarrow Hospice Day Service | G34: 1052-10-06 | I34: Y | J34: complete | K34: Y see Wellbeing | L34: repeat placement
A35: 1052-NC-6561 | B35: Greenquill | C35: Caerel | D35: Adult | E35: Vale Community Pharmacy Network | F35: tbc | G35: 1052-10-06 | I35: Y | J35: 2 outstanding | K35: Y
A36: 1052-NC-9432 | B36: Greenquill | C36: Halion | D36: Mental health | E36: Hollowpick Domiciliary Care | F36: tbc | G36: 1052-10-06 | I36: Y | L36: repeat placement
A37: 1052-NC-6510 | B37: Gridforge | C37: Haskel | D37: Adult | E37: Hollowpick Domiciliary Care | F37: tbc | G37: 1052-10-06 | I37: Y (letter) | J37: complete
A38: 1052-NC-8035 | B38: Guildmark | C38: Rodan | D38: Adult | E38: Deepmarrow Hospice | F38: tbc | G38: 1052-10-06 | I38: Y (letter) | J38: complete
A39: 1052-NC-8721 | B39: Hardfall | C39: Inna | D39: Adult | E39: Riverside Rehabilitation Unit | F39: tbc | G39: 1052-10-06 | I39: Y | J39: complete | L39: repeat placement
A40: 1052-NC-8206 | B40: Honourforge | C40: Norvik | D40: Community | E40: Brinestep Coastal Clinic | F40: tbc | G40: 1052-10-06 | I40: Y | J40: done | L40: lives near Palm Coast
...

Sheet Y2 S2 alloc
A1: Student ID | B1: Surname | C1: Forename | D1: Pathway | E1: Provider | F1: Mentor | G1: Start | H1: End | I1: OH cleared | J1: Mandatory training | K1: Adjustments? | L1: Notes
A2: 1052-NC-0365 | B2: Ashbarrow | C2: Braniel | D2: Adult | E2: Deepmarrow Hospice | F2: Lirien Boughchant | G2: 1053-02-17 | I2: y | J2: complete | K2: Y
A3: 1052-NC-7744 | B3: Bannerstone | C3: Astri | D3: Mental health | E3: Baobab Heights Private Clinic | F3: Ivoryscroll | G3: 1053-02-17 | I3: Y | J3: complete | L3: travel bursary
A4: 1052-NC-7755 | B4: Blazewind | C4: Alira | D4: Adult | E4: Hearthbind Hostel Health Outreach | F4: Merra Hearthbind | G4: 1053-02-17 | I4: Y | J4: 2 outstanding | L4: lives near Palm Coast
A5: 1052-NC-8383 | B5: Bloomjoint | C5: Jonel | D5: Adult | E5: Sandstone Ferry Walk-in Clinic | F5: tbc | G5: 1053-02-17 | I5: N | J5: complete
A6: 1052-NC-9781 | B6: Brambletale | C6: Neren | D6: Community | E6: Malachite Forge First Aid Post | G6: 1053-02-17 | I6: Y | J6: complete
A7: 1052-NC-7854 | B7: Bridgeglen | C7: Halden | D7: Mental health | E7: Vale Community Pharmacy Network | F7: Jostin Clayreach | G7: 1053-02-17 | I7: Y | K7: yes - no nights wk 1-2
A8: 1052-NC-8434 | B8: Brighthaft | C8: Rokka | D8: Adult | E8: Brinestep Coastal Clinic | G8: 1053-02-17 | I8: Y | J8: 2 outstanding | K8: yes - no nights wk 1-2
A9: 1052-NC-8880 | B9: Burnthread | C9: Fenrik | D9: Community | E9: Hollowpick Domiciliary Care | G9: 1053-02-17 | I9: N | J9: complete | L9: swap requested (no)
A10: 1052-NC-6333 | B10: Ceremleaf | C10: Qiraen | D10: Adult | E10: Brinestep Coastal Clinic | F10: Marra Foamveil | G10: 1053-02-17 | I10: Y (letter) | J10: complete | K10: yes - no nights wk 1-2 | L10: repeat placement
A11: 1052-NC-5422 | B11: Cragshield | C11: Agda | D11: Adult | E11: Sandstone Ferry Walk-in Clinic | F11: tbc | G11: 1053-02-17 | I11: Y | J11: complete | K11: yes - no nights wk 1-2
A12: 1052-NC-7540 | B12: Cragshield | C12: Krorik | D12: Mental health | E12: Greywater Vale Infirmary, Outpatients | F12: tbc | G12: 1053-02-17 | I12: pending | J12: complete | K12: Y see Wellbeing
A13: 1052-NC-7607 | B13: Dealroot | C13: Ilyra | D13: Adult | E13: Ashen Reach School Nursing Service | F13: Coalwhisper | G13: 1053-02-17 | I13: Y | J13: complete | K13: Y | L13: ring provider re start date
A14: 1052-NC-5772 | B14: Deepforge | C14: Ulgar | D14: Mental health | E14: Riverside Rehabilitation Unit | F14: Dustmantle | G14: 1053-02-17 | I14: N | J14: complete | K14: Y
A15: 1052-NC-5328 | B15: Deepgrit | C15: Bolrik | D15: Community | E15: Vale Community Pharmacy Network | F15: tbc | G15: 1053-02-17 | I15: Y | J15: 2 outstanding | K15: yes - no nights wk 1-2
A16: 1052-NC-6639 | B16: Deepgrit | C16: Marnie | D16: Mental health | E16: Baobab Heights Private Clinic | G16: 1053-02-17 | I16: Y | J16: complete | L16: swap requested (no)
A17: 1052-NC-8484 | B17: Deepgrit | C17: Storn | D17: Adult | E17: Sandstone Ferry Walk-in Clinic | G17: 1053-02-17 | I17: Y | J17: complete | K17: Y see Wellbeing | L17: repeat placement
A18: 1052-NC-6564 | B18: Dewscroll | C18: Meluin | D18: Adult | E18: Ashen Reach School Nursing Service | F18: Coalwhisper | G18: 1053-02-17 | I18: Y | J18: 2 outstanding | K18: Y | L18: ring provider re start date
A19: 1052-NC-7867 | B19: Draftbit | C19: Morten | D19: Adult | E19: Deepmarrow Hospice | F19: tbc | G19: 1053-02-17 | I19: Y | J19: complete | K19: Y | L19: travel bursary
A20: 1052-NC-8519 | B20: Duskthorn | C20: Saenil | D20: Adult | E20: Palmstrand Maternity Unit | G20: 1053-02-17 | I20: Y | K20: Y see Wellbeing
A21: 1052-NC-9978 | B21: Edgefitter | C21: Nerra | D21: Adult | E21: Hollowpick Community Care | F21: Ashbarrow | G21: 1053-02-17 | I21: Y | J21: complete | K21: yes - no nights wk 1-2 | L21: travel bursary
A22: 1052-NC-8049 | B22: Edgefitter | C22: Sela | D22: Mental health | E22: Brinestep Coastal Clinic | F22: tbc | G22: 1053-02-17 | I22: Y (letter) | J22: complete | K22: yes - no nights wk 1-2
A23: 1052-NC-5442 | B23: Emberlin | C23: Merra | D23: Mental health | E23: Slate District Nursing Service | F23: Delra Linevault | G23: 1053-02-17 | I23: Y | J23: done | K23: Y see Wellbeing | L23: swap requested (no)
A24: 1052-NC-7788 | B24: Emberthorn | C24: Orren | D24: Mental health | E24: Malachite Forge First Aid Post | F24: tbc | G24: 1053-02-17 | I24: pending | J24: complete
A25: 1052-NC-5887 | B25: Flintroot | C25: Durgan | D25: Mental health | E25: Ashen Reach School Nursing Service | F25: tbc | G25: 1053-02-17 | I25: Y | J25: complete | K25: yes - no nights wk 1-2 | L25: travel bursary
A26: 1052-NC-7336 | B26: Flintroot | C26: Rilka | D26: Adult | E26: Greywater Vale Infirmary, Children's Ward | F26: Cliffmarch | G26: 1053-02-17 | I26: y
A27: 1052-NC-7514 | B27: Gearmantle | C27: Ralik | D27: Adult | E27: Flintrock Urgent Care Centre | F27: Firechisel | G27: 1053-02-17 | I27: Y | J27: 2 outstanding | K27: yes - no nights wk 1-2 | L27: swap requested (no)
A28: 1052-NC-7941 | B28: Gemlace | C28: Dremel | D28: Mental health | E28: Malachite Forge First Aid Post | G28: 1053-02-17 | I28: Y | K28: Y see Wellbeing | L28: swap requested (no)
A29: 1052-NC-9300 | B29: Glimmerlock | C29: Wenni | D29: Adult | E29: Palmstrand Maternity Unit | F29: Mirani Horizonchant | G29: 1053-02-17 | I29: Y (letter) | L29: repeat placement
A30: 1052-NC-6789 | B30: Goldmantle | C30: Caerion | D30: Adult | E30: Hollowpick Community Care | F30: Brenik Ashbarrow | G30: 1053-02-17 | I30: Y (letter) | J30: 2 outstanding | K30: Y
A31: 1052-NC-7218 | B31: Goldmantle | C31: Vaeren | D31: Mental health | E31: Deepmarrow Hospice Day Service | F31: Glossfeather | G31: 1053-02-17 | I31: y | J31: complete | K31: yes - no nights wk 1-2 | L31: travel bursary
A32: 1052-NC-5977 | B32: Gravelhack | C32: Enna | D32: Adult | E32: Hollowpick Community Care | F32: Brenik Ashbarrow | G32: 1053-02-17 | I32: Y | L32: repeat placement
A33: 1052-NC-8348 | B33: Gravelhack | C33: Fennik | D33: Community | E33: Riverside Rehabilitation Unit | F33: tbc | G33: 1053-02-17 | I33: Y (letter) | K33: Y
A34: 1052-NC-7874 | B34: Gravethorn | C34: Aerthorn | D34: Adult | E34: Slate District Nursing Service | F34: Linevault | G34: 1053-02-17 | I34: Y | J34: 2 outstanding | L34: swap requested (no)
A35: 1052-NC-6561 | B35: Greenquill | C35: Caerel | D35: Community | E35: Rowanmere Hospice at Home | F35: Blossomvow | G35: 1053-02-17 | I35: Y | J35: done
A36: 1052-NC-9432 | B36: Greenquill | C36: Halion | D36: Adult | E36: Baobab Heights Private Clinic | F36: Ivoryscroll | G36: 1053-02-17 | I36: Y (letter) | J36: 2 outstanding
A37: 1052-NC-6510 | B37: Gridforge | C37: Haskel | D37: Mental health | E37: Millbrook Community Mental Health Team | F37: Caedros Pyrelatch | G37: 1053-02-17 | I37: Y | J37: complete | K37: yes - no nights wk 1-2
A38: 1052-NC-8035 | B38: Guildmark | C38: Rodan | D38: Community | E38: Brinestep Coastal Clinic | F38: Marra Foamveil | G38: 1053-02-17 | I38: y | J38: done | L38: ring provider re start date
A39: 1052-NC-8721 | B39: Hardfall | C39: Inna | D39: Mental health | E39: Riverside Rehabilitation Unit | F39: Elka Dustmantle | G39: 1053-02-17 | I39: Y | J39: done
A40: 1052-NC-8206 | B40: Honourforge | C40: Norvik | D40: Adult | E40: Flintrock Urgent Care Centre | G40: 1053-02-17 | I40: y | J40: complete | L40: travel bursary
...

Sheet Y1 intro
A1: Student ID | B1: Surname | C1: Forename | D1: Pathway | E1: Provider | F1: Mentor | G1: Start | H1: End | I1: OH cleared | J1: Mandatory training | K1: Adjustments? | L1: Notes
A2: 1052-NC-4760 | B2: Anvildancer | C2: Dorek | D2: Mental health | E2: Ashvale Community Nursing Team | G2: 1053-03-03 | I2: Y (letter) | J2: 2 outstanding
A3: 1052-NC-5459 | B3: Ashenline | C3: Fenrik | D3: Mental health | E3: Ashen Reach School Nursing Service | G3: 1053-03-03 | I3: Y | J3: complete | K3: Y | L3: lives near Palm Coast
A4: 1052-NC-0700 | B4: Ashmantle | C4: Maelis | D4: Adult | E4: Yewgrove Elder Care Centre | F4: tbc | G4: 1053-03-03 | I4: y | J4: 2 outstanding | L4: repeat placement
A5: 1052-NC-4908 | B5: Ashmantle | C5: Riven | D5: Adult | E5: Slate District Nursing Service | F5: Delra Linevault | G5: 1053-03-03 | I5: y | J5: complete
A6: 1052-NC-0114 | B6: Ashmantle | C6: Saelith | D6: Community | E6: Deepmarrow Hospice | F6: Boughchant | G6: 1053-03-03 | I6: Y | J6: done | K6: Y see Wellbeing | L6: lives near Palm Coast
A7: 1052-NC-0541 | B7: Basketmark | C7: Vara | D7: Mental health | E7: Hollowpick Domiciliary Care | G7: 1053-03-03 | I7: N | J7: complete | L7: repeat placement
A8: 1052-NC-4033 | B8: Boltline | C8: Delra | D8: Adult | E8: Flintrock Urgent Care Centre | F8: Dorrik Firechisel | G8: 1053-03-03 | I8: pending | J8: 2 outstanding | K8: yes - no nights wk 1-2
A9: 1052-NC-0206 | B9: Breakwave | C9: Coren | D9: Mental health | E9: Deepmarrow Hospice Day Service | G9: 1053-03-03 | I9: Y | J9: 2 outstanding | L9: travel bursary
A10: 1052-NC-0079 | B10: Brightloop | C10: Ossel | D10: Mental health | E10: Greywater Vale Infirmary, Children's Ward | F10: Cliffmarch | G10: 1053-03-03 | I10: Y | J10: complete | K10: Y see Wellbeing | L10: travel bursary
A11: 1052-NC-2419 | B11: Brillstripe | C11: Dremel | D11: Adult | E11: Baobab Heights Private Clinic | F11: Serenya Ivoryscroll | G11: 1053-03-03 | I11: y | K11: yes - no nights wk 1-2 | L11: lives near Palm Coast
A12: 1052-NC-4239 | B12: Cartvale | C12: Calrik | D12: Community | E12: Greywater Vale Infirmary, Outpatients | F12: Agda Frostmantle | G12: 1053-03-03 | I12: Y (letter) | J12: complete
A13: 1052-NC-2984 | B13: Cartvale | C13: Korran | D13: Mental health | E13: Ashen Reach School Nursing Service | F13: tbc | G13: 1053-03-03 | I13: y | J13: done | K13: yes - no nights wk 1-2 | L13: travel bursary
A14: 1052-NC-3243 | B14: Chalklace | C14: Torvik | D14: Mental health | E14: Rowanmere Hospice at Home | F14: Blossomvow | G14: 1053-03-03 | I14: pending | J14: done
A15: 1052-NC-8371 | B15: Chiselhand | C15: Durgan | D15: Community | E15: Deepmarrow Hospice Day Service | F15: Meluin Glossfeather | G15: 1053-03-03 | I15: Y (letter) | J15: done
A16: 1052-NC-4561 | B16: Chiselhand | C16: Thorkel | D16: Adult | E16: Hearthbind Hostel Health Outreach | F16: Hearthbind | G16: 1053-03-03 | I16: y | J16: 2 outstanding
A17: 1052-NC-2350 | B17: Claymantle | C17: Harnel | D17: Adult | E17: Obsidian Vault Infirmary | F17: tbc | G17: 1053-03-03 | I17: Y (letter) | J17: done | K17: yes - no nights wk 1-2
A18: 1052-NC-0828 | B18: Claymantle | C18: Vennel | D18: Community | E18: Vale Community Pharmacy Network | G18: 1053-03-03 | I18: Y | J18: done
A19: 1052-NC-1463 | B19: Coaljaw | C19: Bruk | D19: Adult | E19: Bismuth Quarter Surgery | F19: tbc | G19: 1053-03-03 | I19: Y | J19: done
A20: 1052-NC-2671 | B20: Coralshade | C20: Coren | D20: Adult | E20: Rowanmere Hospice at Home | F20: Blossomvow | G20: 1053-03-03 | I20: Y | L20: travel bursary
A21: 1052-NC-2688 | B21: Coralshade | C21: Mirani | D21: Community | E21: Granite Ridge Prison Healthcare | F21: Astri Garrisonveil | G21: 1053-03-03 | I21: Y | J21: done | K21: Y see Wellbeing
A22: 1052-NC-4216 | B22: Cragburrow | C22: Enna | D22: Adult | E22: Deepmarrow Hospice Day Service | F22: Glossfeather | G22: 1053-03-03 | I22: y | J22: 2 outstanding | K22: Y | L22: ring provider re start date
A23: 1052-NC-2863 | B23: Cragshield | C23: Krorik | D23: Adult | E23: Malachite Forge First Aid Post | F23: tbc | G23: 1053-03-03 | I23: y | J23: complete | L23: swap requested (no)
A24: 1052-NC-2218 | B24: Crownweaver | C24: Qiraen | D24: Adult | E24: Palmstrand Maternity Unit | F24: Mirani Horizonchant | G24: 1053-03-03 | I24: N | J24: done | L24: repeat placement
A25: 1052-NC-3435 | B25: Crumblevale | C25: Kallin | D25: Adult | E25: Malachite Forge First Aid Post | F25: tbc | G25: 1053-03-03 | I25: Y (letter) | J25: complete | K25: Y
A26: 1052-NC-0936 | B26: Deepforge | C26: Tilda | D26: Mental health | E26: Stonebridge Residential Care Home | F26: Matron Gilda Crestguard | G26: 1053-03-03 | I26: pending | J26: 2 outstanding | L26: repeat placement
A27: 1052-NC-4395 | B27: Deepgrit | C27: Marnie | D27: Community | E27: Obsidian Vault Infirmary | F27: tbc | G27: 1053-03-03 | I27: Y | L27: travel bursary
A28: 1052-NC-1144 | B28: Duneweaver | C28: Tivan | D28: Mental health | E28: Slate District Nursing Service | F28: Delra Linevault | G28: 1053-03-03 | I28: Y (letter) | J28: 2 outstanding
A29: 1052-NC-1129 | B29: Duneweaver | C29: Tyrell | D29: Mental health | E29: Hearthbind Hostel Health Outreach | F29: Merra Hearthbind | G29: 1053-03-03 | I29: N | J29: complete | K29: Y see Wellbeing | L29: lives near Palm Coast
A30: 1052-NC-3694 | B30: Duskthorn | C30: Saelith | D30: Adult | E30: Malachite Forge First Aid Post | F30: Bellowsmoke | G30: 1053-03-03 | I30: pending | L30: lives near Palm Coast
A31: 1052-NC-2393 | B31: Emberthorn | C31: Corven | D31: Community | E31: Hollowpick Community Care | G31: 1053-03-03 | I31: N | J31: complete | L31: swap requested (no)
A32: 1052-NC-0449 | B32: Emberthorn | C32: Thorne | D32: Adult | E32: Deepmarrow Hospice Day Service | F32: tbc | G32: 1053-03-03 | I32: Y | J32: complete | K32: Y see Wellbeing | L32: repeat placement
A33: 1052-NC-0217 | B33: Everjudged | C33: Envel | D33: Mental health | E33: Bismuth Quarter Surgery | F33: Gemlace | G33: 1053-03-03 | I33: Y (letter) | J33: complete | K33: Y
A34: 1052-NC-9205 | B34: Everjudged | C34: Oloran | D34: Adult | E34: Rowanmere Hospice at Home | F34: Feyra Blossomvow | G34: 1053-03-03 | I34: Y (letter) | J34: complete | L34: lives near Palm Coast
A35: 1052-NC-3329 | B35: Flameborn | C35: Talien | D35: Community | E35: Greywater Vale Infirmary, Outpatients | F35: Frostmantle | G35: 1053-03-03 | I35: Y | J35: done | L35: lives near Palm Coast
A36: 1052-NC-4232 | B36: Flintroot | C36: Dagna | D36: Mental health | E36: Obsidian Vault Infirmary | G36: 1053-03-03 | I36: Y | J36: complete | L36: swap requested (no)
A37: 1052-NC-1600 | B37: Fogwhisper | C37: Thalen | D37: Adult | E37: Palmstrand Maternity Unit | F37: Mirani Horizonchant | G37: 1053-03-03 | I37: y | J37: complete | K37: yes - no nights wk 1-2 | L37: repeat placement
A38: 1052-NC-1660 | B38: Gildspark | C38: Tirra | D38: Adult | E38: Brinestep Coastal Clinic | G38: 1053-03-03 | I38: Y (letter) | J38: 2 outstanding | K38: Y see Wellbeing | L38: lives near Palm Coast
A39: 1052-NC-3384 | B39: Glyphpetal | C39: Vaelis | D39: Community | E39: Greywater Vale Infirmary, Children's Ward | G39: 1053-03-03 | I39: Y | L39: ring provider re start date
A40: 1052-NC-3658 | B40: Goldmantle | C40: Taelon | D40: Community | E40: Ashvale Community Nursing Team | F40: tbc | G40: 1053-03-03 | I40: Y
...

Sheet Capacity
A1: Provider | B1: Places | C1: Y2 S1 used | D1: Y2 S2 used | E1: Y1 used | F1: Spare | G1: Check
A2: Greywater Vale Infirmary | B2: =INDEX(Providers!E:E,MATCH(A2,Providers!A:A,0)) | C2: =COUNTIF('Y2 S1 alloc'!E:E,A2) | D2: =COUNTIF('Y2 S2 alloc'!E:E,A2) | E2: =COUNTIF('Y1 intro'!E:E,A2) | F2: =B2-MAX(C2:E2) | G2: =IF(F2<0,"OVER","")
A3: Hollowpick Community Care | B3: =INDEX(Providers!E:E,MATCH(A3,Providers!A:A,0)) | C3: =COUNTIF('Y2 S1 alloc'!E:E,A3) | D3: =COUNTIF('Y2 S2 alloc'!E:E,A3) | E3: =COUNTIF('Y1 intro'!E:E,A3) | F3: =B3-MAX(C3:E3) | G3: =IF(F3<0,"OVER","")
A4: Deepmarrow Hospice | B4: =INDEX(Providers!E:E,MATCH(A4,Providers!A:A,0)) | C4: =COUNTIF('Y2 S1 alloc'!E:E,A4) | D4: =COUNTIF('Y2 S2 alloc'!E:E,A4) | E4: =COUNTIF('Y1 intro'!E:E,A4) | F4: =B4-MAX(C4:E4) | G4: =IF(F4<0,"OVER","")
A5: Brinestep Coastal Clinic | B5: =INDEX(Providers!E:E,MATCH(A5,Providers!A:A,0)) | C5: =COUNTIF('Y2 S1 alloc'!E:E,A5) | D5: =COUNTIF('Y2 S2 alloc'!E:E,A5) | E5: =COUNTIF('Y1 intro'!E:E,A5) | F5: =B5-MAX(C5:E5) | G5: =IF(F5<0,"OVER","")
A6: Cragburrow Mine Surgery | B6: =INDEX(Providers!E:E,MATCH(A6,Providers!A:A,0)) | C6: =COUNTIF('Y2 S1 alloc'!E:E,A6) | D6: =COUNTIF('Y2 S2 alloc'!E:E,A6) | E6: =COUNTIF('Y1 intro'!E:E,A6) | F6: =B6-MAX(C6:E6) | G6: =IF(F6<0,"OVER","")
A7: Oakhollow Village Practice | B7: =INDEX(Providers!E:E,MATCH(A7,Providers!A:A,0)) | C7: =COUNTIF('Y2 S1 alloc'!E:E,A7) | D7: =COUNTIF('Y2 S2 alloc'!E:E,A7) | E7: =COUNTIF('Y1 intro'!E:E,A7) | F7: =B7-MAX(C7:E7) | G7: =IF(F7<0,"OVER","")
A8: Stonebridge Residential Care Home | B8: =INDEX(Providers!E:E,MATCH(A8,Providers!A:A,0)) | C8: =COUNTIF('Y2 S1 alloc'!E:E,A8) | D8: =COUNTIF('Y2 S2 alloc'!E:E,A8) | E8: =COUNTIF('Y1 intro'!E:E,A8) | F8: =B8-MAX(C8:E8) | G8: =IF(F8<0,"OVER","")
A9: Ashvale Community Nursing Team | B9: =INDEX(Providers!E:E,MATCH(A9,Providers!A:A,0)) | C9: =COUNTIF('Y2 S1 alloc'!E:E,A9) | D9: =COUNTIF('Y2 S2 alloc'!E:E,A9) | E9: =COUNTIF('Y1 intro'!E:E,A9) | F9: =B9-MAX(C9:E9) | G9: =IF(F9<0,"OVER","")
A10: Greywater Vale Infirmary, Children's Ward | B10: =INDEX(Providers!E:E,MATCH(A10,Providers!A:A,0)) | C10: =COUNTIF('Y2 S1 alloc'!E:E,A10) | D10: =COUNTIF('Y2 S2 alloc'!E:E,A10) | E10: =COUNTIF('Y1 intro'!E:E,A10) | F10: =B10-MAX(C10:E10) | G10: =IF(F10<0,"OVER","")
A11: Millbrook Community Mental Health Team | B11: =INDEX(Providers!E:E,MATCH(A11,Providers!A:A,0)) | C11: =COUNTIF('Y2 S1 alloc'!E:E,A11) | D11: =COUNTIF('Y2 S2 alloc'!E:E,A11) | E11: =COUNTIF('Y1 intro'!E:E,A11) | F11: =B11-MAX(C11:E11) | G11: =IF(F11<0,"OVER","")
A12: Riverside Rehabilitation Unit | B12: =INDEX(Providers!E:E,MATCH(A12,Providers!A:A,0)) | C12: =COUNTIF('Y2 S1 alloc'!E:E,A12) | D12: =COUNTIF('Y2 S2 alloc'!E:E,A12) | E12: =COUNTIF('Y1 intro'!E:E,A12) | F12: =B12-MAX(C12:E12) | G12: =IF(F12<0,"OVER","")
A13: Deepmarrow Hospice Day Service | B13: =INDEX(Providers!E:E,MATCH(A13,Providers!A:A,0)) | C13: =COUNTIF('Y2 S1 alloc'!E:E,A13) | D13: =COUNTIF('Y2 S2 alloc'!E:E,A13) | E13: =COUNTIF('Y1 intro'!E:E,A13) | F13: =B13-MAX(C13:E13) | G13: =IF(F13<0,"OVER","")
... A31: Vale Community Pharmacy Network | B31: =INDEX(Providers!E:E,MATCH(A31,Providers!A:A,0)) | C31: =COUNTIF('Y2 S1 alloc'!E:E,A31) | D31: =COUNTIF('Y2 S2 alloc'!E:E,A31) | E31: =COUNTIF('Y1 intro'!E:E,A31) | F31: =B31-MAX(C31:E31) | G31: =IF(F31<0,"OVER","")

Sheet OH tracker
A1: Student ID | B1: Name | C1: OH status | D1: Detail | E1: Date | F1: Chased
A2: 1052-NC-9978 | B2: Nerra Edgefitter | C2: Pending | F2: xxx
A3: 1052-NC-4251 | B3: Sela Truelock | C3: Cleared | D3: asthma, inhaler | E3: 1053-01-15 | F3: xx
A4: 1052-NC-0828 | B4: Vennel Claymantle | C4: Not started | D4: asthma, inhaler
A5: 1052-NC-2207 | B5: Rilka Oregrind | C5: Cleared | E5: 1052-09-12 | F5: xxx
A6: 1052-NC-9432 | B6: Halion Greenquill | C6: Cleared with restrictions | D6: awaiting vaccination record
A7: 1052-NC-5238 | B7: Rodan Tarryvale | C7: Cleared with restrictions | D7: back problem - no heavy lifting per OH | E7: 1052-10-01 | F7: xxx
A8: 1052-NC-9305 | B8: Skarn Masonflare | C8: Not started | E8: 1052-11-20
A9: 1052-NC-2457 | B9: Thareon Highbark | C9: Pending | F9: x
A10: 1052-NC-2671 | B10: Coren Coralshade | C10: Pending | E10: 1053-01-15
A11: 1052-NC-5769 | B11: Brondel Quarryscribe | C11: Cleared | E11: 1052-10-01 | F11: x
A12: 1052-NC-8323 | B12: Torvik Scalejoint | C12: Not started
A13: 1052-NC-2350 | B13: Harnel Claymantle | C13: Pending | E13: 1052-10-01 | F13: x
A14: 1052-NC-6882 | B14: Caerel Memorybraid | C14: Cleared | D14: back problem - no heavy lifting per OH | E14: 1053-01-15
A15: 1052-NC-1364 | B15: Varnok Ironroot | C15: Pending | D15: needle phobia - OH aware | E15: 1052-11-20 | F15: xxx
A16: 1052-NC-2518 | B16: Garrun Weldspark | C16: Not started | D16: asthma, inhaler | E16: 1052-10-01 | F16: x
A17: 1052-NC-3729 | B17: Marenel Vowroot | C17: Cleared | D17: mental health - see Wellbeing | E17: 1052-11-20
A18: 1052-NC-7514 | B18: Ralik Gearmantle | C18: Pending | E18: 1052-10-01 | F18: x
A19: 1052-NC-2419 | B19: Dremel Brillstripe | C19: Pending | D19: mental health - see Wellbeing | E19: 1052-11-20 | F19: xxx
A20: 1052-NC-2988 | B20: Thessa Notegrip | C20: Cleared | F20: x
A21: 1052-NC-6810 | B21: Elrik Veilwhisper | C21: Cleared | D21: mental health - see Wellbeing | E21: 1052-09-12 | F21: xx
A22: 1052-NC-4610 | B22: Vanya Tomeflower | C22: Cleared | D22: asthma, inhaler | F22: xxx
A23: 1052-NC-0772 | B23: Varnel Scrivenstone | C23: Cleared with restrictions | D23: back problem - no heavy lifting per OH | E23: 1052-10-01 | F23: xx
A24: 1052-NC-8519 | B24: Saenil Duskthorn | C24: Cleared with restrictions | D24: asthma, inhaler | E24: 1052-10-01 | F24: xx
A25: 1052-NC-3835 | B25: Grisel Greymine | C25: Not started | E25: 1052-11-20 | F25: xx
A26: 1052-NC-2182 | B26: Brenik Quietlock | C26: Not started | D26: needle phobia - OH aware | E26: 1053-01-15 | F26: x
A27: 1052-NC-1046 | B27: Storn Knuckleblast | C27: Not started
A28: 1052-NC-7941 | B28: Dremel Gemlace | C28: Cleared with restrictions | D28: back problem - no heavy lifting per OH | E28: 1053-01-15 | F28: x
A29: 1052-NC-6681 | B29: Mirra Sandspire | C29: Not started | E29: 1052-11-20 | F29: x
A30: 1052-NC-0449 | B30: Thorne Emberthorn | C30: Pending | F30: xx
A31: 1052-NC-1551 | B31: Neria Lorebloom | C31: Cleared | E31: 1052-10-01 | F31: xx
A32: 1052-NC-1901 | B32: Omren Plainbrow | C32: Not started | D32: mental health - see Wellbeing | F32: xxx
A33: 1052-NC-1107 | B33: Ilrian Yewmantle | C33: Cleared | D33: back problem - no heavy lifting per OH | E33: 1052-11-20 | F33: xx
A34: 1052-NC-5747 | B34: Gilda Stormhall | C34: Cleared | E34: 1052-10-01 | F34: x
A35: 1052-NC-0936 | B35: Tilda Deepforge | C35: Not started | D35: mental health - see Wellbeing | F35: xx
A36: 1052-NC-7607 | B36: Ilyra Dealroot | C36: Cleared | D36: back problem - no heavy lifting per OH | E36: 1053-01-15
A37: 1052-NC-3906 | B37: Tilda Sheltergrim | C37: Cleared | D37: mental health - see Wellbeing | E37: 1052-10-01 | F37: xx
A38: 1052-NC-4616 | B38: Riella Inkweaver | C38: Cleared | D38: back problem - no heavy lifting per OH | F38: xxx
A39: 1052-NC-2688 | B39: Mirani Coralshade | C39: Cleared | D39: back problem - no heavy lifting per OH | E39: 1053-01-15 | F39: x
A40: 1052-NC-7744 | B40: Astri Bannerstone | C40: Not started | D40: back problem - no heavy lifting per OH | E40: 1052-10-01 | F40: x
...

Sheet Mand training
A1: Student ID | B1: Name | C1: Moving and handling | D1: Infection control | E1: Safeguarding | F1: IG | G1: Complete?
A2: 1052-NC-4760 | B2: Dorek Anvildancer | C2: Y | D2: Y | E2: Y | F2: Y | G2: Y
A3: 1052-NC-5459 | B3: Fenrik Ashenline | C3: Y | D3: Y | E3: N | F3: Y | G3: N
A4: 1052-NC-0700 | B4: Maelis Ashmantle | C4: Y | D4: Y | E4: Y | F4: Y | G4: Y
A5: 1052-NC-4908 | B5: Riven Ashmantle | C5: Y | D5: Y | E5: N | F5: Y | G5: N
A6: 1052-NC-0114 | B6: Saelith Ashmantle | C6: Y | D6: Y | E6: Y | F6: N | G6: N
A7: 1052-NC-0541 | B7: Vara Basketmark | C7: Y | D7: Y | E7: N | F7: Y | G7: N
A8: 1052-NC-4033 | B8: Delra Boltline | C8: N | D8: N | E8: Y | F8: Y | G8: N
A9: 1052-NC-0206 | B9: Coren Breakwave | C9: Y | D9: Y | E9: N | F9: Y | G9: N
A10: 1052-NC-0079 | B10: Ossel Brightloop | C10: Y | D10: Y | E10: Y | F10: Y | G10: Y
A11: 1052-NC-2419 | B11: Dremel Brillstripe | C11: Y | D11: N | E11: Y | F11: Y | G11: N
A12: 1052-NC-4239 | B12: Calrik Cartvale | C12: Y | D12: N | E12: Y | F12: Y | G12: N
... A198: 1052-NC-8027 | B198: Virella Yewmantle | C198: Y | D198: N | E198: N | F198: Y | G198: N

Sheet Mentors
A1: Provider | B1: Mentor | C1: Qualified mentor? | D1: Last update | E1: Notes
A2: Greywater Vale Infirmary | B2: Sister Agda Frostmantle | C2: lapsed | E2: retiring Dec
A3: Hollowpick Community Care | B3: Brenik Ashbarrow | C3: lapsed | D3: 1052 | E3: new
A4: Deepmarrow Hospice | B4: Lirien Boughchant | C4: Y | E4: prefers phone
A5: Brinestep Coastal Clinic | B5: Marra Foamveil | C5: Y | D5: 1052 | E5: new
A6: Cragburrow Mine Surgery | B6: Durgan Brimspade | C6: ? | E6: retiring Dec
A7: Oakhollow Village Practice | B7: Dr Lirien Ferntext | C7: Y | D7: 1051
A8: Stonebridge Residential Care Home | B8: Matron Gilda Crestguard | C8: lapsed | D8: 1052
A9: Ashvale Community Nursing Team | B9: Vaela Kindlebloom | C9: lapsed
A10: Greywater Vale Infirmary, Children's Ward | B10: Sister Hilda Cliffmarch | C10: Y | D10: 1051 | E10: retiring Dec
A11: Millbrook Community Mental Health Team | B11: Caedros Pyrelatch | C11: lapsed | D11: 1050 | E11: prefers phone
A12: Riverside Rehabilitation Unit | B12: Elka Dustmantle | C12: Y | E12: prefers phone
A13: Deepmarrow Hospice Day Service | B13: Meluin Glossfeather | C13: ? | D13: 1050 | E13: prefers phone
A14: Cragburrow Mine Occupational Health Service | B14: Hask Deepgrit | C14: lapsed | D14: 1052 | E14: prefers phone
A15: Bismuth Quarter Surgery | B15: Dr Thessa Gemlace | C15: lapsed | D15: 1052 | E15: retiring Dec
A16: Palmstrand Maternity Unit | B16: Mirani Horizonchant | C16: lapsed | D16: 1051
A17: Hollowpick Domiciliary Care | B17: Calla Claymantle | C17: ? | D17: 1051 | E17: new
A18: Sandstone Ferry Walk-in Clinic | B18: Garril Bargestone | C18: ?
A19: Yewgrove Elder Care Centre | B19: Nethira Duskthorn | C19: lapsed
A20: Obsidian Vault Infirmary | B20: Dr Morthen Glassenclave | C20: lapsed | D20: 1052
A21: Malachite Forge First Aid Post | B21: Brimma Bellowsmoke | C21: ? | D21: 1052
A22: Slate District Nursing Service | B22: Delra Linevault | C22: Y | E22: retiring Dec
A23: Rowanmere Hospice at Home | B23: Feyra Blossomvow | C23: ?
A24: Flintrock Urgent Care Centre | B24: Dorrik Firechisel | C24: Y | D24: 1050
A25: Baobab Heights Private Clinic | B25: Serenya Ivoryscroll | C25: Y | D25: 1052 | E25: prefers phone
A26: Greywater Vale Infirmary, Outpatients | B26: Agda Frostmantle | C26: ? | D26: 1050
A27: Ashen Reach School Nursing Service | B27: Noriel Coalwhisper | C27: lapsed | D27: 1051
A28: Hearthbind Hostel Health Outreach | B28: Merra Hearthbind | C28: lapsed | D28: 1051 | E28: retiring Dec
A29: Palm Coast Ambulance Station | B29: Tivan Breakwave | C29: lapsed | E29: prefers phone
A30: Granite Ridge Prison Healthcare | B30: Astri Garrisonveil | C30: ? | D30: 1051 | E30: retiring Dec
A31: Vale Community Pharmacy Network | B31: Jostin Clayreach | C31: Y | D31: 1050

Sheet Travel
A1: Student ID | B1: Name | C1: Provider | D1: Form received | E1: Amount | F1: Paid
A2: 1052-NC-8412 | B2: Calo Scribemark | C2: Cragburrow Mine Surgery | D2: Y | E2: 40 | F2: N
A3: 1052-NC-5887 | B3: Durgan Flintroot | C3: Brinestep Coastal Clinic | D3: Y | E3: 60
A4: 1052-NC-6518 | B4: Corviel Vowroot | C4: Cragburrow Mine Surgery | D4: N | E4: 85 | F4: N
A5: 1052-NC-6561 | B5: Caerel Greenquill | C5: Cragburrow Mine Surgery | D5: Y | E5: 40 | F5: Y
A6: 1052-NC-5328 | B6: Bolrik Deepgrit | C6: Cragburrow Mine Surgery | D6: N | E6: 60 | F6: Y
A7: 1052-NC-0365 | B7: Braniel Ashbarrow | C7: Brinestep Coastal Clinic | D7: Y | E7: 60
A8: 1052-NC-8484 | B8: Storn Deepgrit | C8: Cragburrow Mine Surgery | D8: Y | E8: 85 | F8: N
A9: 1052-NC-5855 | B9: Korrik Ironloop | C9: Brinestep Coastal Clinic | D9: Y | E9: 40 | F9: N
A10: 1052-NC-8206 | B10: Norvik Honourforge | C10: Brinestep Coastal Clinic | D10: Y | E10: 120 | F10: N
A11: 1052-NC-7854 | B11: Halden Bridgeglen | C11: Cragburrow Mine Surgery | D11: N | E11: 60 | F11: N
A12: 1052-NC-8733 | B12: Orsen Notchtask | C12: Brinestep Coastal Clinic | D12: Y | E12: 40 | F12: N
A13: 1052-NC-6681 | B13: Mirra Sandspire | C13: Brinestep Coastal Clinic | D13: Y | E13: 85 | F13: N

Sheet Issues
A1: Date | B1: Student | C1: Provider | D1: Issue | E1: Action | F1: Closed
A2: 1052-10-09 | B2: Rodan Guildmark | C2: Baobab Heights Private Clinic | D2: wrong site | E2: Sent to main site not outpatients. Rang provider, sorted by 10am | F2: Y
A3: 1052-10-15 | B3: Meluin Dewscroll | C3: Cragburrow Mine Occupational Health Service | D3: no OH clearance | E3: Sent home. OH chased. Restarted following week | F3: Y
A4: 1052-11-02 | B4: Rodan Tarryvale | C4: Hollowpick Domiciliary Care | D4: swap | E4: Two students swapped without telling us. Both placements pulled. Dagna spoke to them | F4: Y
A5: 1052-11-14 | B5: Corviel Thorncounsel | C5: Bismuth Quarter Surgery | D5: documentation error | E5: Medication documentation error, mentor reported. Referred to Nyssa (FtP). Student removed from placement pending | F5: N
A6: 1052-11-28 | B6: Elarion Tomeflower | C6: Oakhollow Village Practice | D6: mentor off sick | E6: No mentor for 2 weeks. Provider found cover week 2 | F6: Y
A7: 1053-01-20 | B7: Vaeren Goldmantle | C7: Sandstone Ferry Walk-in Clinic | D7: storms | E7: Brinestep closed. 6 students reallocated to Greywater OPD at 3 days notice | F7: Y
A8: 1053-02-03 | B8: Ithira Remembrace | C8: Ashen Reach School Nursing Service | D8: OH column | E8: Hesta says OH detail column should not have health notes in. Agreed. Not done yet | F8: N
A9: 1053-02-24 | B9: Storn Deepgrit | C9: Palm Coast Ambulance Station | D9: adjustments | E9: Mentor not told about student adjustments (no nights). Student did nights. Wellbeing involved | F9: N
A10: 1053-03-10 | B10: Ylva Stonebar | C10: Brinestep Coastal Clinic | D10: photo | E10: Student photographed drug chart. FtP referral | F10: N

Sheet Contacts OLD
A1: Provider | B1: Old contact | C1: Old phone | D1: Replaced by | E1: When
A2: Greywater Vale Infirmary | B2: Bolrik Cragburrow | C2: 01632 960513 | D2: Sister Agda Frostmantle | E2: 1052
A3: Hollowpick Community Care | B3: Jessa Claydancer | C3: 01632 960808 | D3: Brenik Ashbarrow | E3: 1050
A4: Deepmarrow Hospice | B4: Jessa Claydancer | C4: 01632 960353 | D4: Lirien Boughchant | E4: 1050
A5: Brinestep Coastal Clinic | B5: Jessa Claydancer | C5: 01632 960517 | D5: Marra Foamveil | E5: 1051
A6: Cragburrow Mine Surgery | B6: Bolrik Cragburrow | C6: 01632 960396 | D6: Durgan Brimspade | E6: 1052
A7: Oakhollow Village Practice | B7: Bolrik Cragburrow | C7: 01632 960229 | D7: Dr Lirien Ferntext | E7: 1051
A8: Stonebridge Residential Care Home | B8: Jessa Claydancer | C8: 01632 960640 | D8: Matron Gilda Crestguard | E8: ?
A9: Ashvale Community Nursing Team | B9: Bolrik Cragburrow | C9: 01632 960305 | D9: Vaela Kindlebloom | E9: ?
A10: Greywater Vale Infirmary, Children's Ward | B10: Enna Frostmantle | C10: 01632 960597 | D10: Sister Hilda Cliffmarch | E10: 1050
A11: Millbrook Community Mental Health Team | B11: Enna Frostmantle | C11: 01632 960508 | D11: Caedros Pyrelatch | E11: 1051
A12: Riverside Rehabilitation Unit | B12: Bolrik Cragburrow | C12: 01632 960544 | D12: Elka Dustmantle | E12: 1052
A13: Deepmarrow Hospice Day Service | B13: Enna Frostmantle | C13: 01632 960945 | D13: Meluin Glossfeather | E13: ?

Sheet Lookups
A1: Pathway
A2: Adult
A3: Community
A4: Mental health
A5: Children (Y2 S2 only)

Sheet Notes
A1: Note
A2: Tab 9 formulas broke when I inserted a column in Providers. Fixed? Check Capacity.
A3: DO NOT sort Y2 S1 alloc by provider, it unlinks the mentor column (not actually linked, just looks wrong)
A4: Hesta has a better version of the OH tracker in her folder. Use that.
A5: Liora: colour coding is in the legend tab (tab 14). Green = done. Yellow = chase. Red = problem. Grey = I don't know.
A6: Handover: everything is in my head and in this file. Writing it down. H
A7: If Brinestep closes for storms ring Agda at Greywater FIRST, she can usually take 4-6 at short notice
